Workbook

Sheet Cover
D12: Comparable Valuation Model | M12: Strictly Confidential
D14: Table of Contents
D16: Summary
D17: Trading Analysis | E17: HVM
D18: Transaction Analysis | E18: GPT
D32: © 2015 to 2024 CFI Education Inc.
D33: This Excel model is for educational purposes only and should not be used for any other reason. All content is Copyright material of CFI Education Inc.
D34: All rights reserved. The contents of this publication, including but not limited to all written material, content layout, images, formulas, and code, are protected
D35: under international copyright and trademark laws. No part of this publication may be modified, manipulated, reproduced, distributed, or transmitted in any
D36: form by any means, including photocopying, recording, or other electronic or mechanical methods, without prior written permission of the publisher,
D37: except in the case of certain noncommercial uses permitted by copyright law.
D39: https://corporatefinanceinstitute.com/

Sheet Summary
B3: Valuation Summary
B5: All figures in USD millions unless stated
B7: Enterprise Value
M32: Comparable Trading and Precedent Transaction Analysis both use LTM EV / EBITDA.
B36: Valuation Graphing Data
B38: All figures in USD millions unless stated
C40: Low | D40: Delta | E40: High | F40: Mid
B42: Comparable Trading Analysis
B43: Precedent Transaction Analysis
B44: DCF Valuation Analysis | C44: 13850 | E44: 22848
B46: =IF(SUM(C46:F46)=4,"COMPLETE","") | C46: ='Summary-R'!C7 -> 0 | D46: ='Summary-R'!D7 -> 0 | E46: ='Summary-R'!E7 -> 0 | F46: ='Summary-R'!F7 -> 0

Sheet Summary-R
B3: Valuation Graphing Data
B5: Learner | C5: =SUM(Summary!C42:C43) -> 0 | D5: =SUM(Summary!D42:D44) -> 0 | E5: =SUM(Summary!E42:E43) -> 0 | F5: =SUM(Summary!F42:F44) -> 0
B6: Correct | C6: =Trading!E32+Transactions!H33 -> 0 | D6: =SUM(Summary!E42:E44)-SUM(Summary!C42:C44) -> 8998 | E6: =Trading!E31+Transactions!H32 -> 0 | F6: =SUM(Summary!C42:C44)+SUM(Summary!D42:D44)/2 -> 13850
B7: Compare | C7: =IFERROR(IF(C5=0,0,IF(C5=C6,1,0)),0) -> 0 | D7: =IFERROR(IF(D5=0,0,IF(D5=D6,1,0)),0) -> 0 | E7: =IFERROR(IF(E5=0,0,IF(E5=E6,1,0)),0) -> 0 | F7: =IFERROR(IF(F5=0,0,IF(F5=F6,1,0)),0) -> 0

Sheet Trading
B3: Comparable Trading Analysis
B5: All figures in USD millions unless stated
D7: Share | E7: Enterprise | G7: EV /
B8: Peer Companies | C8: Ticker | D8: Price | E8: Value | F8: EBITDA | G8: EBITDA | H8: EBITDA Growth | J8: EPS | K8: P / E
D10: (USD/sh) | F10: (LTM) | G10: (LTM) | H10: (FY+1) | I10: (FY+2) | J10: (LTM) | K10: (LTM)
B12: =HVM!F10 -> Harvest Market | C12: HVM
B13: Grocery Getaway | C13: GGY | D13: 16.74 | E13: 18960 | F13: 3874 | H13: 0.08 | I13: 0.07 | J13: 1.87
B14: Gourmet Choice | C14: GCI | D14: 35.6 | E14: 33567 | F14: 5126 | H14: 0.07 | I14: 0.06 | J14: 3.14
B15: Green Grocery | C15: GEG | D15: 31.43 | E15: 28972 | F15: 5238 | H15: 0.07 | I15: 0.07 | J15: 2.87
B16: The Food Emporium | C16: TFE | D16: 11.32 | E16: 5130 | F16: 1131 | H16: 0.03 | I16: 0.02 | J16: 1.21
B18: =IF(SUM(C18:K18)=8,"COMPLETE","") | D18: ='Trading-R'!D21 -> 0 | E18: ='Trading-R'!E21 -> 0 | F18: ='Trading-R'!F21 -> 0 | G18: ='Trading-R'!G21 -> 0 | H18: ='Trading-R'!H21 -> 0 | I18: ='Trading-R'!I21 -> 0 | J18: ='Trading-R'!J21 -> 0 | K18: ='Trading-R'!K21 -> 0
B20: Target Company Valuation
B22: All figures in USD millions unless stated
E24: Enterprise | G24: EV /
B25: Target Company Valuation 1, 2 | E25: Value | F25: EBITDA | G25: EBITDA | H25: EBITDA Growth
F27: (LTM) | G27: (LTM) | H27: (FY+1) | I27: (FY+2)
B29: Average | F29: 3754 | H29: 0.07 | I29: 0.06
B30: Median | F30: =F29 -> 3754 | H30: =H29 -> 0.07 | I30: =I29 -> 0.06
B31: Maximum | F31: =F30 -> 3754 | H31: =H30 -> 0.07 | I31: =I30 -> 0.06
B32: Minimum | F32: =F31 -> 3754 | H32: =H31 -> 0.07 | I32: =I31 -> 0.06
B34: =IF(SUM(E34:G34)=2,"COMPLETE","") | E34: ='Trading-R'!E44 -> 0 | G34: ='Trading-R'!G44 -> 0
I36: Target company valuation based on LTM EV/EBITDA multiple.
I37: Summary results above exclude The Food Emporium.

Sheet Trading-R
B3: Comparable Trading Analysis
B5: All figures in USD millions unless stated
D7: Share | E7: Enterprise | G7: EV /
B8: Peer Companies | C8: Ticker | D8: Price | E8: Value | F8: EBITDA | G8: EBITDA | H8: EBITDA Growth | J8: EPS | K8: P / E
D9: (USD/sh) | F9: (LTM) | G9: (LTM) | H9: (FY+1) | I9: (FY+2) | J9: (LTM) | K9: (LTM)
B11: =HVM!F10 -> Harvest Market | C11: HVM | D11: =HVM!L10 -> 24.9 | E11: =HVM!L25 -> 0 | F11: =HVM!K74 -> 0 | G11: =E11/F11 -> #DIV/0! | H11: =HVM!I96 -> 0 | I11: =HVM!J96 -> 0 | J11: =HVM!K63 -> 0 | K11: =D11/J11 -> #DIV/0!
B12: Grocery Getaway | C12: GGY | D12: 16.74 | E12: 18960 | F12: 3874 | G12: =E12/F12 -> 4.8941662 | H12: 0.08 | I12: 0.07 | J12: 1.87 | K12: =IFERROR($D12/J12,"NA") -> 8.9518717
B13: Gourmet Choice | C13: GCI | D13: 35.6 | E13: 33567 | F13: 5126 | G13: =E13/F13 -> 6.5483808 | H13: 0.07 | I13: 0.06 | J13: 3.14 | K13: =IFERROR($D13/J13,"NA") -> 11.33758
B14: Green Grocery | C14: GEG | D14: 31.43 | E14: 28972 | F14: 5238 | G14: =E14/F14 -> 5.5311187 | H14: 0.07 | I14: 0.07 | J14: 2.87 | K14: =IFERROR($D14/J14,"NA") -> 10.95122
B15: The Food Emporium | C15: TFE | D15: 11.32 | E15: 5130 | F15: 1131 | G15: =E15/F15 -> 4.535809 | H15: 0.04 | I15: 0.03 | J15: 1.21 | K15: =IFERROR($D15/J15,"NA") -> 9.3553719
B19: =Trading!B12 -> Harvest Market | D19: =Trading!D12 -> 0 | E19: =Trading!E12 -> 0 | F19: =Trading!F12 -> 0 | G19: =SUM(Trading!G12:G16) -> 0 | H19: =Trading!H12 -> 0 | I19: =Trading!I12 -> 0 | J19: =Trading!J12 -> 0 | K19: =SUM(Trading!K12:K16) -> 0 | L19: Learner
B20: =B11 -> Harvest Market | D20: =D11 -> 24.9 | E20: =E11 -> 0 | F20: =F11 -> 0 | G20: =SUM(G11:G15) -> #DIV/0! | H20: =H11 -> 0 | I20: =I11 -> 0 | J20: =J11 -> 0 | K20: =SUM(K11:K15) -> #DIV/0! | L20: Correct
D21: =IFERROR(IF(D19=0,0,IF(D19=D20,1,0)),0) -> 0 | E21: =IFERROR(IF(E19=0,0,IF(E19=E20,1,0)),0) -> 0 | F21: =IFERROR(IF(F19=0,0,IF(F19=F20,1,0)),0) -> 0 | G21: =IFERROR(IF(G19=0,0,IF(G19=G20,1,0)),0) -> 0 | H21: =IFERROR(IF(H19=0,0,IF(H19=H20,1,0)),0) -> 0 | I21: =IFERROR(IF(I19=0,0,IF(I19=I20,1,0)),0) -> 0 | J21: =IFERROR(IF(J19=0,0,IF(J19=J20,1,0)),0) -> 0 | K21: =IFERROR(IF(K19=0,0,IF(K19=K20,1,0)),0) -> 0 | L21: Compare
B27: Target Company Valuation
B29: All figures in USD millions unless stated
E31: Enterprise | G31: EV /
B32: Target Company Valuation 1, 2 | E32: Value | F32: EBITDA | G32: EBITDA | H32: EBITDA Growth
F33: (LTM) | G33: (LTM) | H33: (FY+1) | I33: (FY+2)
B35: Average | E35: =F35*G35 -> #DIV/0! | F35: 3754 | G35: =AVERAGE(G$11:G$14) -> #DIV/0! | H35: 0.07 | I35: 0.06
B36: Median | E36: =F36*G36 -> #DIV/0! | F36: =F$35 -> 3754 | G36: =MEDIAN(G$11:G$14) -> #DIV/0! | H36: =H$35 -> 0.07 | I36: =I$35 -> 0.06
B37: Maximum | E37: =F37*G37 -> #DIV/0! | F37: =F$35 -> 3754 | G37: =MAX(G$11:G$14) -> #DIV/0! | H37: =H$35 -> 0.07 | I37: =I$35 -> 0.06
B38: Minimum | E38: =F38*G38 -> #DIV/0! | F38: =F$35 -> 3754 | G38: =MIN(G$11:G$14) -> #DIV/0! | H38: =H$35 -> 0.07 | I38: =I$35 -> 0.06
E42: =SUM(Trading!E29:E32) -> 0 | G42: =SUM(Trading!G29:G32) -> 0 | H42: Learner
E43: =SUMPRODUCT(Trading!F29:F32,Trading!G29:G32) -> 0 | G43: =AVERAGE(Trading!G12:G15)+MEDIAN(Trading!G12:G15)+MAX(Trading!G12:G15)+MIN(Trading!G12:G15) -> #DIV/0! | H43: Correct
E44: =IFERROR(IF(E42=0,0,IF(E42=E43,1,0)),0) -> 0 | G44: =IFERROR(IF(G42=0,0,IF(G42=G43,1,0)),0) -> 0 | H44: Compare
I46: Target company valuation based on LTM EV/EBITDA multiple.
I47: Summary results above exclude The Food Emporium.

Sheet HVM
B3: =CONCATENATE($F$10&": Enterprise Value") -> Harvest Market: Enterprise Value
B5: All figures in USD millions unless stated
B8: Company Information | H8: Market Capitalization | L8: =IF(K13=1,"COMPLETE","")
B10: Company Name | F10: Harvest Market | H10: Share Price | J10: (USD/sh) | L10: 24.9
B11: Analysis Date | E11: (YYYY-MM-DD) | F11: 45484 | H11: Shares Outstanding | J11: (FD mm) | L11: 788.6
H13: Market Capitalization | J13: (FD) | K13: ='HVM-R'!R12 -> 0
B17: Net Debt | F17: =IF(SUM(E20:E25)=4,"COMPLETE","") | H17: Enterprise Value | L17: =IF(SUM(K19:K25)=6,"COMPLETE","")
H19: Market Capitalization | J19: (FD) | K19: ='HVM-R'!W18 -> 0
H20: Plus: Preferred Stock | K20: ='HVM-R'!W19 -> 0
B21: Current Borrowings | E21: ='HVM-R'!R20 -> 0 | H21: Plus: Net Debt | K21: ='HVM-R'!W20 -> 0
B22: Non-Current Borrowings | E22: ='HVM-R'!R21 -> 0 | H22: Plus: Non-Controlling Interest | K22: ='HVM-R'!W21 -> 0
B23: Less: Cash & Cash Equivalents | E23: ='HVM-R'!R22 -> 0 | H23: Less: Investments in Affiliates / JVs | K23: ='HVM-R'!W22 -> 0
B25: Net Debt | E25: ='HVM-R'!R23 -> 0 | H25: Enterprise Value | K25: ='HVM-R'!W23 -> 0
B29: =CONCATENATE($F$10&": Income Statement") -> Harvest Market: Income Statement
B31: All figures in USD millions unless stated
H32: Latest | I32: Current | J32: Previous
H33: Fiscal Year | I33: YTD 1 | J33: YTD 1 | K33: LTM
B34: Income Statement | D34: =IF(SUM(L34:L63)=16,"COMPLETE","") | I34: 45473 | J34: =IFERROR(EDATE(I34,-12),"") -> 45107 | L34: ='HVM-R'!R33 -> 0
B37: Revenue | L37: ='HVM-R'!R36 -> 0
B38: Cost of Sales | L38: ='HVM-R'!R37 -> 0
B40: Gross Profit | H40: =SUM(H37:H38) -> 0 | I40: =SUM(I37:I38) -> 0 | J40: =SUM(J37:J38) -> 0 | L40: ='HVM-R'!R38 -> 0
B42: Selling, General & Administrative | L42: ='HVM-R'!R40 -> 0
B44: Operating Income (EBIT) | H44: =H40+H42 -> 0 | I44: =I40+I42 -> 0 | J44: =J40+J42 -> 0 | L44: ='HVM-R'!R41 -> 0
B46: Interest Expense | L46: ='HVM-R'!R43 -> 0
B47: Interest Income | L47: ='HVM-R'!R44 -> 0
B48: Income from Equity Investments 2 | L48: ='HVM-R'!R45 -> 0
B50: Earnings Before Tax (EBT) | H50: =SUM(H44:H48) -> 0 | I50: =SUM(I44:I48) -> 0 | J50: =SUM(J44:J48) -> 0 | L50: ='HVM-R'!R46 -> 0
B52: Taxes | L52: ='HVM-R'!R48 -> 0
B54: Consolidated Net Income | H54: =H50+H52 -> 0 | I54: =I50+I52 -> 0 | J54: =J50+J52 -> 0 | L54: ='HVM-R'!R49 -> 0
B56: Non-Controlling Interest | L56: ='HVM-R'!R51 -> 0
B58: Net Income to Company | H58: =H54+H56 -> 0 | I58: =I54+I56 -> 0 | J58: =J54+J56 -> 0 | L58: ='HVM-R'!R52 -> 0
B61: Weighted Average Diluted Shares | G61: (mm) | L61: ='HVM-R'!R55 -> 0
B63: Diluted EPS | G63: (USD/sh) | H63: =H58/H61 -> #DIV/0! | I63: =I58/I61 -> #DIV/0! | J63: =J58/J61 -> #DIV/0! | L63: ='HVM-R'!R57 -> 0
B67: EBITDA Calculation | D67: =IF(SUM(L68:L74)=6,"COMPLETE","")
B68: Consolidated Net Income | L68: ='HVM-R'!R62 -> 0
B69: Plus: Taxes | L69: ='HVM-R'!R63 -> 0
B70: Less: Income from Equity Investments | L70: ='HVM-R'!R64 -> 0
B71: Plus: Net Interest | L71: ='HVM-R'!R65 -> 0
B72: Plus: Depreciation | L72: ='HVM-R'!R66 -> 0
B74: EBITDA | L74: ='HVM-R'!R67 -> 0
...

Sheet HVM-R
B3: =CONCATENATE($F$10&": Enterprise Value") -> Harvest Market: Enterprise Value
B5: All figures in USD millions unless stated
B8: Company Information | H8: Market Capitalization | O8: Market Capitalization | P8: Learner | Q8: Correct | R8: Compare
B10: Company Name | F10: Harvest Market | H10: Share Price | K10: (USD/sh) | L10: 24.9
B11: Analysis Date | E11: (YYYY-MM-DD) | F11: 45484 | H11: Shares Outstanding | K11: (FD mm) | L11: 788.6
H12: Market Capitalization | K12: (FD) | L12: =L10*L11 -> 19636.14 | O12: Market Capitalization | P12: =HVM!L13 -> 0 | Q12: =L11*L10 -> 19636.14 | R12: =IFERROR(IF(P12=0,0,IF(P12=Q12,1,0)),0) -> 0
B16: Net Debt | H16: Enterprise Value | O16: Net Debt | P16: Learner | Q16: Correct | R16: Compare | T16: Enterprise Value | U16: Learner | V16: Correct | W16: Compare
H18: Market Capitalization | K18: (FD) | L18: =L12 -> 19636.14 | T18: Market Capitalization | U18: =HVM!L19 -> 0 | V18: =HVM!L13 -> 0 | W18: =IFERROR(IF(U18=0,0,IF(U18=V18,1,0)),0) -> 0
H19: Plus: Preferred Stock | L19: 25 | T19: Plus: Preferred Stock | U19: =HVM!L20 -> 0 | V19: =L19 -> 25 | W19: =IFERROR(IF(U19=0,0,IF(U19=V19,1,0)),0) -> 0
B20: Current Borrowings | F20: 2365 | H20: Plus: Net Debt | L20: =F23 -> 10972 | O20: Current Borrowings | P20: =HVM!F21 -> 0 | Q20: =F20 -> 2365 | R20: =IFERROR(IF(P20=0,0,IF(P20=Q20,1,0)),0) -> 0 | T20: Plus: Net Debt | U20: =HVM!L21 -> 0 | V20: =HVM!F25 -> 0 | W20: =IFERROR(IF(U20=0,0,IF(U20=V20,1,0)),0) -> 0
B21: Non-Current Borrowings | F21: 11959 | H21: Plus: Non-Controlling Interest | L21: 22 | O21: Non-Current Borrowings | P21: =HVM!F22 -> 0 | Q21: =F21 -> 11959 | R21: =IFERROR(IF(P21=0,0,IF(P21=Q21,1,0)),0) -> 0 | T21: Plus: Non-Controlling Interest | U21: =HVM!L22 -> 0 | V21: =L21 -> 22 | W21: =IFERROR(IF(U21=0,0,IF(U21=V21,1,0)),0) -> 0
B22: Less: Cash & Cash Equivalents | F22: -3352 | H22: Less: Investments in Affiliates / JVs | L22: -92 | O22: Less: Cash & Cash Equivalents | P22: =HVM!F23 -> 0 | Q22: =F22 -> -3352 | R22: =IFERROR(IF(P22=0,0,IF(P22=Q22,1,0)),0) -> 0 | T22: Less: Investments in Affiliates / JVs | U22: =HVM!L23 -> 0 | V22: =L22 -> -92 | W22: =IFERROR(IF(U22=0,0,IF(U22=V22,1,0)),0) -> 0
B23: Net Debt | F23: =SUM(F20:F22) -> 10972 | H23: Enterprise Value | L23: =SUM(L18:L22) -> 30563.14 | O23: Net Debt | P23: =HVM!F25 -> 0 | Q23: =SUM(HVM!F21:F23) -> 0 | R23: =IFERROR(IF(P23=0,0,IF(P23=Q23,1,0)),0) -> 0 | T23: Enterprise Value | U23: =HVM!L25 -> 0 | V23: =SUM(HVM!L19:L23) -> 0 | W23: =IFERROR(IF(U23=0,0,IF(U23=V23,1,0)),0) -> 0
B27: =CONCATENATE($F$10&": Income Statement") -> Harvest Market: Income Statement
B29: All figures in USD millions unless stated
H31: Latest | I31: Current | J31: Previous | O31: Income Statement | P31: Learner | Q31: Correct | R31: Compare
H32: Fiscal Year | I32: YTD 1 | J32: YTD 1 | K32: LTM
B33: Income Statement | H33: 45291 | I33: 45473 | J33: =IFERROR(EDATE(I33,-12),"") -> 45107 | K33: =IF(I33,I33,H33) -> 45473 | O33: Headings | P33: =SUM(HVM!H34:K34) -> 90580 | Q33: =SUM(H33:K33) -> 181344 | R33: =IFERROR(IF(P33=0,0,IF(P33=Q33,1,0)),0) -> 0
B36: Revenue | H36: 68187 | I36: 36139 | J36: 32048 | K36: =H36+I36-J36 -> 72278 | O36: =B36 -> Revenue | P36: =SUM(HVM!H37:K37) -> 0 | Q36: =SUM(H36:K36) -> 208652 | R36: =IFERROR(IF(P36=0,0,IF(P36=Q36,1,0)),0) -> 0
B37: Cost of Sales | H37: -63338 | I37: -33569 | J37: -29769 | K37: =H37+I37-J37 -> -67138 | O37: =B37 -> Cost of Sales | P37: =SUM(HVM!H38:K38) -> 0 | Q37: =SUM(H37:K37) -> -193814 | R37: =IFERROR(IF(P37=0,0,IF(P37=Q37,1,0)),0) -> 0
B38: Gross Profit | H38: =SUM(H36:H37) -> 4849 | I38: =SUM(I36:I37) -> 2570 | J38: =SUM(J36:J37) -> 2279 | K38: =H38+I38-J38 -> 5140 | O38: =B38 -> Gross Profit | P38: =HVM!K40 -> 0 | Q38: =HVM!H40+HVM!I40-HVM!J40 -> 0 | R38: =IFERROR(IF(P38=0,0,IF(P38=Q38,1,0)),0) -> 0
B40: Selling, General & Administrative | H40: -2028 | I40: -1075 | J40: -953 | K40: =H40+I40-J40 -> -2150 | O40: =B40 -> Selling, General & Administrative | P40: =SUM(HVM!H42:K42) -> 0 | Q40: =SUM(H40:K40) -> -6206 | R40: =IFERROR(IF(P40=0,0,IF(P40=Q40,1,0)),0) -> 0
B41: Operating Income (EBIT) | H41: =H38+H40 -> 2821 | I41: =I38+I40 -> 1495 | J41: =J38+J40 -> 1326 | K41: =H41+I41-J41 -> 2990 | O41: =B41 -> Operating Income (EBIT) | P41: =HVM!K44 -> 0 | Q41: =HVM!H44+HVM!I44-HVM!J44 -> 0 | R41: =IFERROR(IF(P41=0,0,IF(P41=Q41,1,0)),0) -> 0
B43: Interest Expense | H43: -805 | I43: -427 | J43: -378 | K43: =H43+I43-J43 -> -854 | O43: =B43 -> Interest Expense | P43: =SUM(HVM!H46:K46) -> 0 | Q43: =SUM(H43:K43) -> -2464 | R43: =IFERROR(IF(P43=0,0,IF(P43=Q43,1,0)),0) -> 0
B44: Interest Income | H44: 267 | I44: 142 | J44: 125 | K44: =H44+I44-J44 -> 284 | O44: =B44 -> Interest Income | P44: =SUM(HVM!H47:K47) -> 0 | Q44: =SUM(H44:K44) -> 818 | R44: =IFERROR(IF(P44=0,0,IF(P44=Q44,1,0)),0) -> 0
B45: Income from Equity Investments 2 | H45: 6 | I45: 3 | J45: 3 | K45: =H45+I45-J45 -> 6 | O45: =B45 -> Income from Equity Investments 2 | P45: =SUM(HVM!H48:K48) -> 0 | Q45: =SUM(H45:K45) -> 18 | R45: =IFERROR(IF(P45=0,0,IF(P45=Q45,1,0)),0) -> 0
B46: Earnings Before Tax (EBT) | H46: =SUM(H41:H45) -> 2289 | I46: =SUM(I41:I45) -> 1213 | J46: =SUM(J41:J45) -> 1076 | K46: =H46+I46-J46 -> 2426 | O46: =B46 -> Earnings Before Tax (EBT) | P46: =HVM!K50 -> 0 | Q46: =HVM!H50+HVM!I50-HVM!J50 -> 0 | R46: =IFERROR(IF(P46=0,0,IF(P46=Q46,1,0)),0) -> 0
B48: Taxes | H48: -568 | I48: -278 | J48: -267 | K48: =H48+I48-J48 -> -579 | O48: =B48 -> Taxes | P48: =SUM(HVM!H52:K52) -> 0 | Q48: =SUM(H48:K48) -> -1692 | R48: =IFERROR(IF(P48=0,0,IF(P48=Q48,1,0)),0) -> 0
B49: Consolidated Net Income | H49: =H46+H48 -> 1721 | I49: =I46+I48 -> 935 | J49: =J46+J48 -> 809 | K49: =H49+I49-J49 -> 1847 | O49: =B49 -> Consolidated Net Income | P49: =HVM!K54 -> 0 | Q49: =HVM!H54+HVM!I54-HVM!J54 -> 0 | R49: =IFERROR(IF(P49=0,0,IF(P49=Q49,1,0)),0) -> 0
B51: Non-Controlling Interest | H51: -3 | I51: -2 | J51: -1 | K51: =H51+I51-J51 -> -4 | O51: =B51 -> Non-Controlling Interest | P51: =SUM(HVM!H56:K56) -> 0 | Q51: =SUM(H51:K51) -> -10 | R51: =IFERROR(IF(P51=0,0,IF(P51=Q51,1,0)),0) -> 0
B52: Net Income to Company | H52: =H49+H51 -> 1718 | I52: =I49+I51 -> 933 | J52: =J49+J51 -> 808 | K52: =H52+I52-J52 -> 1843 | O52: =B52 -> Net Income to Company | P52: =HVM!K58 -> 0 | Q52: =HVM!H58+HVM!I58-HVM!J58 -> 0 | R52: =IFERROR(IF(P52=0,0,IF(P52=Q52,1,0)),0) -> 0
B55: Weighted Average Diluted Shares | G55: (mm) | H55: 764.2 | I55: 773.2 | J55: 752.8 | K55: =K52/K57 -> 773.89829 | O55: =B55 -> Weighted Average Diluted Shares | P55: =SUM(HVM!H61:K61) -> 0 | Q55: =SUM(H55:K55) -> 3064.0983 | R55: =IFERROR(IF(P55=0,0,IF(P55=Q55,1,0)),0) -> 0
B57: Diluted EPS | G57: (USD/sh) | H57: =H52/H55 -> 2.2481026 | I57: =I52/I55 -> 1.2066736 | J57: =J52/J55 -> 1.0733262 | K57: =H57+I57-J57 -> 2.3814499 | O57: =B57 -> Diluted EPS | P57: =HVM!K63 -> 0 | Q57: =HVM!H63+HVM!I63-HVM!J63 -> #DIV/0! | R57: =IFERROR(IF(P57=0,0,IF(P57=Q57,1,0)),0) -> 0
B61: EBITDA Calculation | O61: EBITDA Calculation | P61: Learner | Q61: Correct | R61: Compare
B62: Consolidated Net Income | H62: =H49 -> 1721 | I62: =I49 -> 935 | J62: =J49 -> 809 | K62: =H62+I62-J62 -> 1847 | O62: =B62 -> Consolidated Net Income | P62: =SUM(HVM!H68:K68) -> 0 | Q62: =SUM(HVM!H54:K54) -> 0 | R62: =IFERROR(IF(P62=0,0,IF(P62=Q62,1,0)),0) -> 0
B63: Plus: Taxes | H63: =-H48 -> 568 | I63: =-I48 -> 278 | J63: =-J48 -> 267 | K63: =H63+I63-J63 -> 579 | O63: =B63 -> Plus: Taxes | P63: =SUM(HVM!H69:K69) -> 0 | Q63: =-SUM(HVM!H52:K52) -> 0 | R63: =IFERROR(IF(P63=0,0,IF(P63=Q63,1,0)),0) -> 0
B64: Less: Income from Equity Investments | H64: =-H45 -> -6 | I64: =-I45 -> -3 | J64: =-J45 -> -3 | K64: =H64+I64-J64 -> -6 | O64: =B64 -> Less: Income from Equity Investments | P64: =SUM(HVM!H70:K70) -> 0 | Q64: =-SUM(HVM!H48:K48) -> 0 | R64: =IFERROR(IF(P64=0,0,IF(P64=Q64,1,0)),0) -> 0
B65: Plus: Net Interest | H65: =-SUM(H43:H44) -> 538 | I65: =-SUM(I43:I44) -> 285 | J65: =-SUM(J43:J44) -> 253 | K65: =H65+I65-J65 -> 570 | O65: =B65 -> Plus: Net Interest | P65: =SUM(HVM!H71:K71) -> 0 | Q65: =-SUM(HVM!H46:K47) -> 0 | R65: =IFERROR(IF(P65=0,0,IF(P65=Q65,1,0)),0) -> 0
B66: Plus: Depreciation | H66: 1744 | I66: 451 | J66: 872 | K66: =H66+I66-J66 -> 1323 | O66: =B66 -> Plus: Depreciation | P66: =SUM(HVM!H72:K72) -> 0 | Q66: =SUM(H66:K66) -> 4390 | R66: =IFERROR(IF(P66=0,0,IF(P66=Q66,1,0)),0) -> 0
B67: EBITDA | H67: =SUM(H62:H66) -> 4565 | I67: =SUM(I62:I66) -> 1946 | J67: =SUM(J62:J66) -> 2198 | K67: =SUM(K62:K66) -> 4313 | O67: =B67 -> EBITDA | P67: =SUM(HVM!H74:K74) -> 0 | Q67: =SUM(HVM!H68:K72) -> 0 | R67: =IFERROR(IF(P67=0,0,IF(P67=Q67,1,0)),0) -> 0
...

Sheet Transactions
B3: Precedent Transaction Analysis
B5: All figures in USD millions unless stated
E7: Offer | F7: Premium | G7: Offer | H7: Transaction | J7: EV /
B8: Announcement Date | C8: Acquirer | D8: Target | E8: Price | F8: Paid | G8: Type | H8: Value | I8: EBITDA | J8: EBITDA | K8: EBITDA Growth | M8: EPS | N8: P / E
B10: (YYYY-MM-DD) | E10: (USD/sh) | I10: (LTM) | J10: (LTM) | K10: (FY+1) | L10: (FY+2) | M10: (LTM) | N10: (LTM)
B12: =GPT!F12 -> 45112
B13: 45357 | C13: Pure Pantry | D13: Fresh Eats | E13: 43.12 | F13: 0.256 | G13: Cash | H13: 34621 | I13: 6355 | K13: 0.09 | L13: 0.08 | M13: 4.56
B14: 45277 | C14: World Fare Market | D14: Fresh Market | E14: 19.8 | F14: 0.22 | G14: Stock | H14: 32671 | I14: 4521 | K14: 0.1 | L14: 0.09 | M14: 1.94
B15: 45243 | C15: Harvest Basket | D15: Global Cuisine | E15: 48.97 | F15: 0.285 | G15: Mix | H15: 37543 | I15: 7124 | K15: 0.12 | L15: 0.11 | M15: 4.52
B16: 43879 | C16: Country Harvest | D16: QuickStop Market | E16: 16.75 | F16: 0.205 | G16: Cash | H16: 25876 | I16: 3566 | K16: 0.07 | L16: 0.07 | M16: 1.2
B18: =IF(SUM(C18:N18)=12,"COMPLETE","") | C18: ='Transactions-R'!C19 -> 0 | D18: ='Transactions-R'!D19 -> 0 | E18: ='Transactions-R'!E19 -> 0 | F18: ='Transactions-R'!F19 -> 0 | G18: ='Transactions-R'!G19 -> 0 | H18: ='Transactions-R'!H19 -> 0 | I18: ='Transactions-R'!I19 -> 0 | J18: ='Transactions-R'!J19 -> 0 | ... N18: ='Transactions-R'!N19 -> 0
B21: Target Company Valuation
B23: All figures in USD millions unless stated
H25: Enterprise | J25: EV /
B26: Target Company Valuation 1, 2 | H26: Value | I26: EBITDA | J26: EBITDA | K26: EBITDA Growth
I28: (LTM) | J28: (LTM) | K28: (FY+1) | L28: (FY+2)
B30: Average | I30: =Trading!F29 -> 3754 | K30: =Trading!H29 -> 0.07 | L30: =Trading!I29 -> 0.06
B31: Median | I31: =Trading!F30 -> 3754 | K31: =Trading!H30 -> 0.07 | L31: =Trading!I30 -> 0.06
B32: Maximum | I32: =Trading!F31 -> 3754 | K32: =Trading!H31 -> 0.07 | L32: =Trading!I31 -> 0.06
B33: Minimum | I33: =Trading!F32 -> 3754 | K33: =Trading!H32 -> 0.07 | L33: =Trading!I32 -> 0.06
B35: =IF(SUM(H35:J35)=2,"COMPLETE","") | H35: ='Transactions-R'!H37 -> 0 | J35: ='Transactions-R'!J37 -> 0
L38: Target company valuation based on LTM EV/EBITDA multiple.
L39: Summary results above exclude the acquisition of QuickStop Market by Country Harvest.

Sheet Transactions-R
B3: Precedent Transaction Analysis
B5: All figures in USD millions unless stated
E7: Offer | F7: Premium | G7: Offer | H7: Transaction | J7: EV /
B8: Date | C8: Acquirer | D8: Target | E8: Price | F8: Paid | G8: Type | H8: Value | I8: EBITDA | J8: EBITDA | K8: EBITDA Growth | M8: EPS | N8: P / E
B9: (YYYY-MM-DD) | E9: (USD/sh) | I9: (LTM) | J9: (LTM) | K9: (FY+1) | L9: (FY+2) | M9: (LTM) | N9: (LTM)
B11: =GPT!F12 -> 45112 | C11: =GPT!F9 -> Nature’s Choice | D11: =GPT!L9 -> Golden Pantry | E11: =GPT!F24 -> 0 | F11: =GPT!F25 -> 0 | G11: =GPT!F26 -> #VALUE! | H11: =GPT!L37 -> 0 | I11: =GPT!K95 -> 3450 | J11: =H11/I11 -> 0 | K11: =GPT!I116 -> 0.077470572 | L11: =GPT!J116 -> 0.09171748 | M11: =GPT!K84 -> 0.54624306 | N11: =E11/M11 -> 0
B12: 45357 | C12: Pure Pantry | D12: Fresh Eats | E12: 43.12 | F12: 0.256 | G12: Cash | H12: 34621 | I12: 6355 | J12: =H12/I12 -> 5.4478363 | K12: 0.09 | L12: 0.08 | M12: 4.56 | N12: =E12/M12 -> 9.4561404
B13: 45277 | C13: World Fare Market | D13: Fresh Market | E13: 19.8 | F13: 0.22 | G13: Stock | H13: 32671 | I13: 4521 | J13: =H13/I13 -> 7.2264986 | K13: 0.1 | L13: 0.09 | M13: 1.94 | N13: =E13/M13 -> 10.206186
B14: 45243 | C14: Harvest Basket | D14: Global Cuisine | E14: 48.97 | F14: 0.285 | G14: Mix | H14: 37543 | I14: 7124 | J14: =H14/I14 -> 5.2699326 | K14: 0.12 | L14: 0.11 | M14: 4.52 | N14: =E14/M14 -> 10.834071
B15: 43879 | C15: Country Harvest | D15: QuickStop Market | E15: 16.75 | F15: 0.205 | G15: Cash | H15: 25876 | I15: 3566 | J15: =H15/I15 -> 7.2563096 | K15: 0.07 | L15: 0.07 | M15: 1.2 | N15: =E15/M15 -> 13.958333
B17: =Transactions!B12 -> 45112 | C17: =Transactions!C12 -> 0 | D17: =Transactions!D12 -> 0 | E17: =Transactions!E12 -> 0 | F17: =Transactions!F12 -> 0 | G17: =Transactions!G12 -> 0 | H17: =Transactions!H12 -> 0 | I17: =Transactions!I12 -> 0 | J17: =SUM(Transactions!J12:J16) -> 0 | K17: =Transactions!K12 -> 0 | L17: =Transactions!L12 -> 0 | M17: =Transactions!M12 -> 0 | N17: =SUM(Transactions!N12:N16) -> 0 | O17: Learner
B18: =GPT!F12 -> 45112 | C18: =GPT!F9 -> Nature’s Choice | D18: =GPT!L9 -> Golden Pantry | E18: =GPT!F24 -> 0 | F18: =GPT!F25 -> 0 | G18: =GPT!F26 -> #VALUE! | H18: =GPT!L37 -> 0 | I18: =GPT!K95 -> 3450 | J18: {=SUMPRODUCT(Transactions!H12:H16,1/Transactions!I12:I16)} -> #DIV/0! | K18: =GPT!I116 -> 0.077470572 | L18: =GPT!J116 -> 0.09171748 | M18: =GPT!K84 -> 0.54624306 | N18: {=SUMPRODUCT(Transactions!E12:E16,1/Transactions!M12:M16)} -> #DIV/0! | O18: Correct
C19: =IFERROR(IF(C17=0,0,IF(C17=C18,1,0)),0) -> 0 | D19: =IFERROR(IF(D17=0,0,IF(D17=D18,1,0)),0) -> 0 | E19: =IFERROR(IF(E17=0,0,IF(E17=E18,1,0)),0) -> 0 | F19: =IFERROR(IF(F17=0,0,IF(F17=F18,1,0)),0) -> 0 | G19: =IFERROR(IF(G17=0,0,IF(G17=G18,1,0)),0) -> 0 | H19: =IFERROR(IF(H17=0,0,IF(H17=H18,1,0)),0) -> 0 | I19: =IFERROR(IF(I17=0,0,IF(I17=I18,1,0)),0) -> 0 | J19: =IFERROR(IF(J17=0,0,IF(J17=J18,1,0)),0) -> 0 | ... N19: =IFERROR(IF(N17=0,0,IF(N17=N18,1,0)),0) -> 0 | O19: Compare
B22: Target Company Valuation
B24: All figures in USD millions unless stated
H26: Enterprise | J26: EV /
B27: Target Company Valuation 1, 2 | H27: Value | I27: EBITDA | J27: EBITDA | K27: EBITDA Growth
I28: (LTM) | J28: (LTM) | K28: (FY+1) | L28: (FY+2)
B30: Average | H30: =I30*J30 -> 16840.695 | I30: =Trading!F29 -> 3754 | J30: =AVERAGE(J$11:J$14) -> 4.4860669 | K30: =Trading!H29 -> 0.07 | L30: =Trading!I29 -> 0.06
B31: Median | H31: =I31*J31 -> 20117.252 | I31: =I$30 -> 3754 | J31: =MEDIAN(J$11:J$14) -> 5.3588845 | K31: =K$30 -> 0.07 | L31: =L$30 -> 0.06
B32: Maximum | H32: =I32*J32 -> 27128.276 | I32: =I$30 -> 3754 | J32: =MAX(J$11:J$14) -> 7.2264986 | K32: =K$30 -> 0.07 | L32: =L$30 -> 0.06
B33: Minimum | H33: =I33*J33 -> 0 | I33: =I$30 -> 3754 | J33: =MIN(J$11:J$14) -> 0 | K33: =K$30 -> 0.07 | L33: =L$30 -> 0.06
G35: Learner | H35: =SUM(Transactions!H30:H33) -> 0 | J35: =SUM(Transactions!J30:J33) -> 0
G36: Correct | H36: =SUMPRODUCT(Transactions!I30:I33,Transactions!J30:J33) -> 0 | J36: =AVERAGE(Transactions!J12:J15)+MEDIAN(Transactions!J12:J15)+MAX(Transactions!J12:J15)+MIN(Transactions!J12:J15) -> #DIV/0!
G37: Compare | H37: =IFERROR(IF(H35=0,0,IF(H35=H36,1,0)),0) -> 0 | J37: =IFERROR(IF(J35=0,0,IF(J35=J36,1,0)),0) -> 0
L40: Target company valuation based on LTM EV/EBITDA multiple.
L41: Summary results above exclude the acquisition of QuickStop Market by Country Harvest.

Sheet GPT
B3: =CONCATENATE($L$9&": Transaction Value") -> Golden Pantry: Transaction Value
B5: All figures in USD millions unless stated
B7: Acquirer | F7: =IF(E12=1,"COMPLETE","") | H7: Target | L7: =IF(K10=1,"COMPLETE","")
B9: Company | F9: Nature’s Choice | H9: Company | L9: Golden Pantry
B10: Stock Price | D10: (USD/sh) | F10: 5 | H10: Stock Price | J10: (USD/sh) | K10: ='GPT-R'!X10 -> 0
B12: Announcement Date | D12: (YYYY-MM-DD) | F12: 45112
B16: Consideration Details | F16: =IF(SUM(E18:E25)=5,"COMPLETE","") | H16: Equity Offer Value | L16: =IF(SUM(K18:K21)=2,"COMPLETE","")
B18: Cash Offer | D18: (USD/sh) | E18: ='GPT-R'!S18 -> 0 | H18: Total Offer Price per Share | J18: (USD/sh) | K18: ='GPT-R'!X18 -> 0
H19: Shares Outstanding | J19: (FD mm) | L19: 2781.5
B21: Exchange Ratio 1 | E21: ='GPT-R'!S20 -> 0 | H21: Equity Offer Value | J21: (FD) | K21: ='GPT-R'!X20 -> 0
B22: Implied Equity Offer Price | D22: (USD/sh) | E22: ='GPT-R'!S21 -> 0
B24: Total Offer Price | D24: (USD/sh) | E24: ='GPT-R'!S23 -> 0
B25: Premium Paid | E25: ='GPT-R'!S24 -> 0
B26: Type of Offer | F26: {=_xlfn.IFS(AND(F18,F21),"Mix",F18,"Cash",F21,"Stock")} -> #VALUE!
B29: Net Debt | F29: =IF(E37=1,"COMPLETE","") | H29: Transaction Value | L29: =IF(SUM(K31:K41)=5,"COMPLETE","")
H31: Equity Offer Value | J31: (FD) | K31: ='GPT-R'!X30 -> 0
H32: Plus: Preferred Stock | L32: 0
B33: Current Borrowings | F33: 96 | H33: Plus: Net Debt | K33: ='GPT-R'!X32 -> 0
B34: Non-Current Borrowings | F34: 1885 | H34: Plus: Non-Controlling Interest | L34: 0
B35: Less: Cash & Cash Equivalents | F35: -274 | H35: Less: Investments in Affiliates/JVs | L35: -31
B37: Net Debt | E37: ='GPT-R'!S36 -> 0 | H37: Transaction Value | K37: ='GPT-R'!X35 -> 0
H39: Announced Synergies | K39: ='GPT-R'!X37 -> 0
H41: Synergies as a Percent of Transaction Value | K41: ='GPT-R'!X38 -> 0
L45: The exchange ratio is multiplied by the acquirer's share price to obtain the per-share-value of the stock the target will receive.
B49: =CONCATENATE($L$9&": Income Statement") -> Golden Pantry: Income Statement
B51: All figures in USD millions unless stated
H53: Latest | I53: Current | J53: Previous
H54: Fiscal Year | I54: YTD 1 | J54: YTD 1 | K54: LTM
B55: Income Statement | H55: 44926 | I55: 45107 | J55: =IFERROR(EDATE(I55,-12),"") -> 44742 | K55: =IF(I55,I55,H55) -> 45107
B58: Revenue | H58: 54550 | I58: 28911 | J58: 25638 | K58: =H58+I58-J58 -> 57823
B59: Cost of Sales | H59: -50670 | I59: -26855 | J59: -23815 | K59: =H59+I59-J59 -> -53710
B61: Gross Profit | H61: =SUM(H58:H59) -> 3880 | I61: =SUM(I58:I59) -> 2056 | J61: =SUM(J58:J59) -> 1823 | K61: =H61+I61-J61 -> 4113
B63: Selling, General & Administrative | H63: -1622 | I63: -860 | J63: -762 | K63: =H63+I63-J63 -> -1720
B65: Operating Income (EBIT) | H65: =H61+H63 -> 2258 | I65: =I61+I63 -> 1196 | J65: =J61+J63 -> 1061 | K65: =H65+I65-J65 -> 2393
B67: Interest Expense | H67: -644 | I67: -342 | J67: -302 | K67: =H67+I67-J67 -> -684
B68: Interest Income | H68: 214 | I68: 114 | J68: 100 | K68: =H68+I68-J68 -> 228
B69: Income from Equity Investments 2 | H69: 5 | I69: 2 | J69: 2 | K69: =H69+I69-J69 -> 5
B71: Earnings Before Tax (EBT) | H71: =SUM(H65:H69) -> 1833 | I71: =SUM(I65:I69) -> 970 | J71: =SUM(J65:J69) -> 861 | K71: =H71+I71-J71 -> 1942
B73: Taxes | H73: -454 | I73: -222 | J73: -214 | K73: =H73+I73-J73 -> -462
B75: Consolidated Net Income | H75: =H71+H73 -> 1379 | I75: =I71+I73 -> 748 | J75: =J71+J73 -> 647 | K75: =H75+I75-J75 -> 1480
...

Sheet GPT-R
B3: =CONCATENATE($L$9&": Transaction Value") -> Golden Pantry: Transaction Value
B5: All figures in USD millions unless stated
B7: Acquirer | H7: Target | N7: Excel Links | U7: Target | V7: Learner | W7: Correct | X7: Compare
B9: Company | F9: Nature’s Choice | H9: Company | L9: Golden Pantry
B10: Stock Price | E10: (USD/sh) | F10: 5 | H10: Stock Price | K10: (USD/sh) | L10: 4.42 | N10: =GPT!L10 -> 0 | U10: =H10 -> Stock Price | V10: =GPT!L10 -> 0 | W10: ='GPT-R'!L10 -> 4.42 | X10: =IFERROR(IF(V10=0,0,IF(V10=W10,1,0)),0) -> 0
B12: Announcement Date | E12: (YYYY-MM-DD) | F12: 45112 | N12: =GPT!F12 -> 45112
B16: Consideration Details | H16: Equity Offer Value | P16: Consideration | Q16: Learner | R16: Correct | S16: Compare | U16: Equity Offer | V16: Learner | W16: Correct | X16: Compare
B18: Cash Offer | E18: (USD/sh) | F18: 2 | H18: Total Offer Price per Share | K18: (USD/sh) | L18: =F23 -> 5.5 | N18: =GPT!F18 -> 0 | P18: =B18 -> Cash Offer | Q18: =GPT!F18 -> 0 | R18: =F18 -> 2 | S18: =IFERROR(IF(Q18=0,0,IF(Q18=R18,1,0)),0) -> 0 | U18: =H18 -> Total Offer Price per Share | V18: =GPT!L18 -> 0 | W18: =GPT!F24 -> 0 | X18: =IFERROR(IF(V18=0,0,IF(V18=W18,1,0)),0) -> 0
H19: Fully Diluted Shares Outstanding | K19: (FD mm) | L19: 2781.5
B20: Exchange Ratio 1 | F20: 0.7 | H20: Equity Offer Value | K20: (FD) | L20: =L18*L19 -> 15298.25 | N20: =GPT!F21 -> 0 | P20: =B20 -> Exchange Ratio 1 | Q20: =GPT!F21 -> 0 | R20: =F20 -> 0.7 | S20: =IFERROR(IF(Q20=0,0,IF(Q20=R20,1,0)),0) -> 0 | U20: =H20 -> Equity Offer Value | V20: =GPT!L21 -> 0 | W20: =GPT!L18*GPT!L19 -> 0 | X20: =IFERROR(IF(V20=0,0,IF(V20=W20,1,0)),0) -> 0
B21: Implied Equity Offer Price | E21: (USD/sh) | F21: =F20*F10 -> 3.5 | P21: =B21 -> Implied Equity Offer Price | Q21: =GPT!F22 -> 0 | R21: =GPT!F10*GPT!F21 -> 0 | S21: =IFERROR(IF(Q21=0,0,IF(Q21=R21,1,0)),0) -> 0
B23: Total Offer Price | E23: (USD/sh) | F23: =F21+F18 -> 5.5 | P23: =B23 -> Total Offer Price | Q23: =GPT!F24 -> 0 | R23: =GPT!F22+GPT!F18 -> 0 | S23: =IFERROR(IF(Q23=0,0,IF(Q23=R23,1,0)),0) -> 0
B24: Premium Paid | F24: =F23/L10-1 -> 0.24434389 | P24: =B24 -> Premium Paid | Q24: =GPT!F25 -> 0 | R24: =GPT!F24/GPT!L10-1 -> #DIV/0! | S24: =IFERROR(IF(Q24=0,0,IF(Q24=R24,1,0)),0) -> 0
B25: Type of Offer | F25: {=_xlfn.IFS(AND(F18,F20),"Mix",F18,"Cash",F20,"Stock")} -> Mix
B28: Net Debt | H28: Transaction Value | P28: Net Debt | Q28: Learner | R28: Correct | S28: Compare | U28: Transaction Value | V28: Learner | W28: Correct | X28: Compare
H30: Equity Offer Value | K30: (FD) | L30: =L20 -> 15298.25 | U30: =H30 -> Equity Offer Value | V30: =GPT!L31 -> 0 | W30: =GPT!L21 -> 0 | X30: =IFERROR(IF(V30=0,0,IF(V30=W30,1,0)),0) -> 0
H31: Plus: Preferred Stock | L31: 0
H32: Plus: Net Debt | L32: =F36 -> 1707 | U32: =H32 -> Plus: Net Debt | V32: =GPT!L33 -> 0 | W32: =GPT!F37 -> 0 | X32: =IFERROR(IF(V32=0,0,IF(V32=W32,1,0)),0) -> 0
B33: Current Borrowings | F33: 96 | H33: Plus: Non-Controlling Interest | L33: 0
B34: Non-Current Borrowings | F34: 1885 | H34: Less: Investments in Affiliates/JVs | L34: -31
B35: Less: Cash & Cash Equivalents | F35: -274 | H35: Transaction Value | L35: =SUM(L30:L34) -> 16974.25 | U35: =H35 -> Transaction Value | V35: =GPT!L37 -> 0 | W35: =SUM(GPT!L31:L35) -> -31 | X35: =IFERROR(IF(V35=0,0,IF(V35=W35,1,0)),0) -> 0
B36: Net Debt | F36: =SUM(F33:F35) -> 1707 | P36: =B36 -> Net Debt | Q36: =GPT!F37 -> 0 | R36: =SUM(GPT!F33:F35) -> 1707 | S36: =IFERROR(IF(Q36=0,0,IF(Q36=R36,1,0)),0) -> 0
H37: Announced Synergies | L37: 250 | N37: =GPT!L39 -> 0 | U37: =H37 -> Announced Synergies | V37: =GPT!L39 -> 0 | W37: =L37 -> 250 | X37: =IFERROR(IF(V37=0,0,IF(V37=W37,1,0)),0) -> 0
H38: Synergies as a Percent of Transaction Value | L38: =L37/L35 -> 0.014728191 | U38: Synergies as a Percent | V38: =GPT!L41 -> 0 | W38: =GPT!L39/GPT!L37 -> #DIV/0! | X38: =IFERROR(IF(V38=0,0,IF(V38=W38,1,0)),0) -> 0
L42: The exchange ratio is multiplied by the acquirer's share price to obtain the per-share-value of the stock the target will receive.
B46: =CONCATENATE($L$9&": Income Statement") -> Golden Pantry: Income Statement
B48: All figures in USD millions unless stated
H50: Latest | I50: Current | J50: Previous
H51: Fiscal Year | I51: YTD 1 | J51: YTD 1 | K51: LTM
B52: Income Statement | H52: 44926 | I52: 45107 | J52: =IFERROR(EDATE(I52,-12),"") -> 44742 | K52: =IF(I52,I52,H52) -> 45107
B55: Revenue | H55: 54550 | I55: 28911 | J55: 25638 | K55: =H55+I55-J55 -> 57823
B56: Cost of Sales | H56: -50670 | I56: -26855 | J56: -23815 | K56: =H56+I56-J56 -> -53710
B57: Gross Profit | H57: =SUM(H55:H56) -> 3880 | I57: =SUM(I55:I56) -> 2056 | J57: =SUM(J55:J56) -> 1823 | K57: =H57+I57-J57 -> 4113
B59: Selling, General & Administrative | H59: -1622 | I59: -860 | J59: -762 | K59: =H59+I59-J59 -> -1720
B60: Operating Income (EBIT) | H60: =H57+H59 -> 2258 | I60: =I57+I59 -> 1196 | J60: =J57+J59 -> 1061 | K60: =H60+I60-J60 -> 2393
B62: Interest Expense | H62: -644 | I62: -342 | J62: -302 | K62: =H62+I62-J62 -> -684
B63: Interest Income | H63: 214 | I63: 114 | J63: 100 | K63: =H63+I63-J63 -> 228
B64: Income from Equity Investments 2 | H64: 5 | I64: 2 | J64: 2 | K64: =H64+I64-J64 -> 5
B65: Earnings Before Tax (EBT) | H65: =SUM(H60:H64) -> 1833 | I65: =SUM(I60:I64) -> 970 | J65: =SUM(J60:J64) -> 861 | K65: =H65+I65-J65 -> 1942
B67: Taxes | H67: -454 | I67: -222 | J67: -214 | K67: =H67+I67-J67 -> -462
...
