Workbook
Name Covar: 'MVO - Efficient Frontier'!$B$9:$K$18
Name Returns: 'MVO - Efficient Frontier'!$B$3:$K$3
Name Weights: 'MVO - Efficient Frontier'!$B$5:$K$5

Sheet Input Data
A1: Efficient Frontier Analysis - Data
B3: Correlation Coefficients | O3: Correlation Coefficients
B4: =B24 -> AAPL | C4: =C24 -> HOG | D4: =D24 -> DIS | E4: =E24 -> WMT | F4: =F24 -> BBY | G4: =G24 -> AMZN | H4: =H24 -> GS | I4: =I24 -> GOOG | ... L4: =L24 -> S&P500 | O4: =B4 -> AAPL | P4: =C4 -> HOG | Q4: =D4 -> DIS | R4: =E4 -> WMT | S4: =F4 -> BBY | T4: =G4 -> AMZN | U4: =H4 -> GS | V4: =I4 -> GOOG | ... X4: =K4 -> MSFT
A5: =B24 -> AAPL | B5: =CORREL($N$26:$N$144,N$26:N$144) -> 1 | C5: =CORREL($N$26:$N$144,O$26:O$144) -> 0.30080876 | D5: =CORREL($N$26:$N$144,P$26:P$144) -> 0.35297345 | E5: =CORREL($N$26:$N$144,Q$26:Q$144) -> 0.18952562 | F5: =CORREL($N$26:$N$144,R$26:R$144) -> 0.27709876 | G5: =CORREL($N$26:$N$144,S$26:S$144) -> 0.39878332 | H5: =CORREL($N$26:$N$144,T$26:T$144) -> 0.36863107 | I5: =CORREL($N$26:$N$144,U$26:U$144) -> 0.38520194 | ... L5: =CORREL($N$26:$N$144,X$26:X$144) -> 0.56478965 | N5: =A5 -> AAPL | O5: {=(MMULT(TRANSPOSE(Z26:AI144),Z26:AI144)/119)} -> 0.0062683291 | P5: 0.0021650927 | Q5: 0.0019005461 | R5: 0.00073522416 | S5: 0.0024860194 | T5: 0.0025490706 | U5: 0.0024429231 | V5: 0.0019782212 | W5: 0.0013409445 | X5: 0.0021984751
A6: =C24 -> HOG | B6: =CORREL($O$26:$O$144,N$26:N$144) -> 0.30080876 | C6: =CORREL($O$26:$O$144,O$26:O$144) -> 1 | D6: =CORREL($O$26:$O$144,P$26:P$144) -> 0.34606237 | E6: =CORREL($O$26:$O$144,Q$26:Q$144) -> 0.13248369 | F6: =CORREL($O$26:$O$144,R$26:R$144) -> 0.41324979 | G6: =CORREL($O$26:$O$144,S$26:S$144) -> 0.17841024 | H6: =CORREL($O$26:$O$144,T$26:T$144) -> 0.45476675 | I6: =CORREL($O$26:$O$144,U$26:U$144) -> 0.30964624 | ... L6: =CORREL($O$26:$O$144,X$26:X$144) -> 0.55407158 | N6: =A6 -> HOG | O6: 0.0021650927 | P6: 0.0082645702 | Q6: 0.0021395626 | R6: 0.00059013112 | S6: 0.0042571289 | T6: 0.0013094801 | U6: 0.0034605155 | V6: 0.0018259397 | W6: 0.0021653216 | X6: 0.0012973234
A7: =D24 -> DIS | B7: =CORREL($P$26:$P$144,N$26:N$144) -> 0.35297345 | C7: =CORREL($P$26:$P$144,O$26:O$144) -> 0.34606237 | D7: =CORREL($P$26:$P$144,P$26:P$144) -> 1 | E7: =CORREL($P$26:$P$144,Q$26:Q$144) -> 0.22448191 | F7: =CORREL($P$26:$P$144,R$26:R$144) -> 0.31603961 | G7: =CORREL($P$26:$P$144,S$26:S$144) -> 0.27616098 | H7: =CORREL($P$26:$P$144,T$26:T$144) -> 0.57661092 | I7: =CORREL($P$26:$P$144,U$26:U$144) -> 0.42007671 | ... L7: =CORREL($P$26:$P$144,X$26:X$144) -> 0.72086963 | N7: =A7 -> DIS | O7: 0.0019005461 | P7: 0.0021395626 | Q7: 0.0046250981 | R7: 0.00074802785 | S7: 0.0024355442 | T7: 0.0015163231 | U7: 0.0032823531 | V7: 0.001853103 | W7: 0.0017526183 | X7: 0.0016172431
A8: =E24 -> WMT | B8: =CORREL($Q$26:$Q$144,N$26:N$144) -> 0.18952562 | C8: =CORREL($Q$26:$Q$144,O$26:O$144) -> 0.13248369 | D8: =CORREL($Q$26:$Q$144,P$26:P$144) -> 0.22448191 | E8: =CORREL($Q$26:$Q$144,Q$26:Q$144) -> 1 | F8: =CORREL($Q$26:$Q$144,R$26:R$144) -> 0.23165745 | G8: =CORREL($Q$26:$Q$144,S$26:S$144) -> 0.13233948 | H8: =CORREL($Q$26:$Q$144,T$26:T$144) -> 0.10674469 | I8: =CORREL($Q$26:$Q$144,U$26:U$144) -> 0.08724597 | ... L8: =CORREL($Q$26:$Q$144,X$26:X$144) -> 0.30319027 | N8: =A8 -> WMT | O8: 0.00073522416 | P8: 0.00059013112 | Q8: 0.00074802785 | R8: 0.0024007774 | S8: 0.0012862229 | T8: 0.0005235213 | U8: 0.00043778836 | V8: 0.00027728847 | W8: 0.00059103623 | X8: 0.00032422959
A9: =F24 -> BBY | B9: =CORREL($R$26:$R$144,N$26:N$144) -> 0.27709876 | C9: =CORREL($R$26:$R$144,O$26:O$144) -> 0.41324979 | D9: =CORREL($R$26:$R$144,P$26:P$144) -> 0.31603961 | E9: =CORREL($R$26:$R$144,Q$26:Q$144) -> 0.23165745 | F9: =CORREL($R$26:$R$144,R$26:R$144) -> 1 | G9: =CORREL($R$26:$R$144,S$26:S$144) -> 0.26014246 | H9: =CORREL($R$26:$R$144,T$26:T$144) -> 0.40361176 | I9: =CORREL($R$26:$R$144,U$26:U$144) -> 0.22066094 | ... L9: =CORREL($R$26:$R$144,X$26:X$144) -> 0.54231027 | N9: =A9 -> BBY | O9: 0.0024860194 | P9: 0.0042571289 | Q9: 0.0024355442 | R9: 0.0012862229 | S9: 0.012840681 | T9: 0.0023799851 | U9: 0.0038282457 | V9: 0.0016219221 | W9: 0.0025563997 | X9: 0.0019526734
A10: =G24 -> AMZN | B10: =CORREL($S$26:$S$144,N$26:N$144) -> 0.39878332 | C10: =CORREL($S$26:$S$144,O$26:O$144) -> 0.17841024 | D10: =CORREL($S$26:$S$144,P$26:P$144) -> 0.27616098 | E10: =CORREL($S$26:$S$144,Q$26:Q$144) -> 0.13233948 | F10: =CORREL($S$26:$S$144,R$26:R$144) -> 0.26014246 | G10: =CORREL($S$26:$S$144,S$26:S$144) -> 1 | H10: =CORREL($S$26:$S$144,T$26:T$144) -> 0.26664615 | I10: =CORREL($S$26:$S$144,U$26:U$144) -> 0.46596702 | ... L10: =CORREL($S$26:$S$144,X$26:X$144) -> 0.54813848 | N10: =A10 -> AMZN | O10: 0.0025490706 | P10: 0.0013094801 | Q10: 0.0015163231 | R10: 0.0005235213 | S10: 0.0023799851 | T10: 0.0065183542 | U10: 0.0018019646 | V10: 0.0024402518 | W10: 0.0016845749 | X10: 0.0021806291
A11: =H24 -> GS | B11: =CORREL($T$26:$T$144,N$26:N$144) -> 0.36863107 | C11: =CORREL($T$26:$T$144,O$26:O$144) -> 0.45476675 | D11: =CORREL($T$26:$T$144,P$26:P$144) -> 0.57661092 | E11: =CORREL($T$26:$T$144,Q$26:Q$144) -> 0.10674469 | F11: =CORREL($T$26:$T$144,R$26:R$144) -> 0.40361176 | G11: =CORREL($T$26:$T$144,S$26:S$144) -> 0.26664615 | H11: =CORREL($T$26:$T$144,T$26:T$144) -> 1 | I11: =CORREL($T$26:$T$144,U$26:U$144) -> 0.36262382 | ... L11: =CORREL($T$26:$T$144,X$26:X$144) -> 0.73011084 | N11: =A11 -> GS | O11: 0.0024429231 | P11: 0.0034605155 | Q11: 0.0032823531 | R11: 0.00043778836 | S11: 0.0038282457 | T11: 0.0018019646 | U11: 0.0070062225 | V11: 0.0019688326 | W11: 0.0020984724 | X11: 0.0019719049
A12: =I24 -> GOOG | B12: =CORREL($U$26:$U$144,N$26:N$144) -> 0.38520194 | C12: =CORREL($U$26:$U$144,O$26:O$144) -> 0.30964624 | D12: =CORREL($U$26:$U$144,P$26:P$144) -> 0.42007671 | E12: =CORREL($U$26:$U$144,Q$26:Q$144) -> 0.08724597 | F12: =CORREL($U$26:$U$144,R$26:R$144) -> 0.22066094 | G12: =CORREL($U$26:$U$144,S$26:S$144) -> 0.46596702 | H12: =CORREL($U$26:$U$144,T$26:T$144) -> 0.36262382 | I12: =CORREL($U$26:$U$144,U$26:U$144) -> 1 | ... L12: =CORREL($U$26:$U$144,X$26:X$144) -> 0.59127872 | N12: =A12 -> GOOG | O12: 0.0019782212 | P12: 0.0018259397 | Q12: 0.001853103 | R12: 0.00027728847 | S12: 0.0016219221 | T12: 0.0024402518 | U12: 0.0019688326 | V12: 0.0042074695 | W12: 0.001644533 | X12: 0.0016715542
A13: =J24 -> HD | B13: =CORREL($V$26:$V$144,N$26:N$144) -> 0.31549216 | C13: =CORREL($V$26:$V$144,O$26:O$144) -> 0.44367601 | D13: =CORREL($V$26:$V$144,P$26:P$144) -> 0.48004344 | E13: =CORREL($V$26:$V$144,Q$26:Q$144) -> 0.22469418 | F13: =CORREL($V$26:$V$144,R$26:R$144) -> 0.42023131 | G13: =CORREL($V$26:$V$144,S$26:S$144) -> 0.38866462 | H13: =CORREL($V$26:$V$144,T$26:T$144) -> 0.46699793 | I13: =CORREL($V$26:$V$144,U$26:U$144) -> 0.47226502 | ... L13: =CORREL($V$26:$V$144,X$26:X$144) -> 0.70318335 | N13: =A13 -> HD | O13: 0.0013409445 | P13: 0.0021653216 | Q13: 0.0017526183 | R13: 0.00059103623 | S13: 0.0025563997 | T13: 0.0016845749 | U13: 0.0020984724 | V13: 0.001644533 | W13: 0.0028819913 | X13: 0.001116458
A14: =K24 -> MSFT | B14: =CORREL($W$26:$W$144,N$26:N$144) -> 0.47969271 | C14: =CORREL($W$26:$W$144,O$26:O$144) -> 0.24652194 | D14: =CORREL($W$26:$W$144,P$26:P$144) -> 0.41080177 | E14: =CORREL($W$26:$W$144,Q$26:Q$144) -> 0.11431262 | F14: =CORREL($W$26:$W$144,R$26:R$144) -> 0.29768233 | G14: =CORREL($W$26:$W$144,S$26:S$144) -> 0.46658447 | H14: =CORREL($W$26:$W$144,T$26:T$144) -> 0.40696914 | I14: =CORREL($W$26:$W$144,U$26:U$144) -> 0.44517158 | ... L14: =CORREL($W$26:$W$144,X$26:X$144) -> 0.59625141 | N14: =A14 -> MSFT | O14: 0.0021984751 | P14: 0.0012973234 | Q14: 0.0016172431 | R14: 0.00032422959 | S14: 0.0019526734 | T14: 0.0021806291 | U14: 0.0019719049 | V14: 0.0016715542 | W14: 0.001116458 | X14: 0.0033509278
A15: =L24 -> S&P500 | B15: =CORREL($X$26:$X$144,N$26:N$144) -> 0.56478965 | C15: =CORREL($X$26:$X$144,O$26:O$144) -> 0.55407158 | D15: =CORREL($X$26:$X$144,P$26:P$144) -> 0.72086963 | E15: =CORREL($X$26:$X$144,Q$26:Q$144) -> 0.30319027 | F15: =CORREL($X$26:$X$144,R$26:R$144) -> 0.54231027 | G15: =CORREL($X$26:$X$144,S$26:S$144) -> 0.54813848 | H15: =CORREL($X$26:$X$144,T$26:T$144) -> 0.73011084 | I15: =CORREL($X$26:$X$144,U$26:U$144) -> 0.59127872 | ... L15: =CORREL($X$26:$X$144,X$26:X$144) -> 1
A17: Annualized | M17: Monthly
A18: Mean | B18: =N18*12 -> 0.28762797 | C18: =O18*12 -> 0.073437427 | D18: =P18*12 -> 0.17853932 | E18: =Q18*12 -> 0.14314562 | F18: =R18*12 -> 0.23562107 | G18: =S18*12 -> 0.33239044 | H18: =T18*12 -> 0.11891398 | I18: =U18*12 -> 0.20102305 | ... L18: =X18*12 -> 0.1349193 | M18: Mean | N18: =AVERAGE(N26:N144) -> 0.023968997 | O18: =AVERAGE(O26:O144) -> 0.0061197856 | P18: =AVERAGE(P26:P144) -> 0.014878276 | Q18: =AVERAGE(Q26:Q144) -> 0.011928802 | R18: =AVERAGE(R26:R144) -> 0.019635089 | S18: =AVERAGE(S26:S144) -> 0.027699203 | T18: =AVERAGE(T26:T144) -> 0.0099094984 | U18: =AVERAGE(U26:U144) -> 0.016751921 | ... X18: =AVERAGE(X26:X144) -> 0.011243275
A19: Stdev | B19: =SQRT(12)*N21 -> 0.27542223 | C19: =SQRT(12)*O21 -> 0.31625197 | D19: =SQRT(12)*P21 -> 0.23658302 | E19: =SQRT(12)*Q21 -> 0.1704508 | F19: =SQRT(12)*R21 -> 0.39420046 | G19: =SQRT(12)*S21 -> 0.28086141 | H19: =SQRT(12)*T21 -> 0.29118236 | I19: =SQRT(12)*U21 -> 0.22564909 | ... L19: =SQRT(12)*X21 -> 0.13923649 | M19: Variance | N19: =VAR(N26:N144) -> 0.0063214505 | O19: =VAR(O26:O144) -> 0.0083346089 | P19: =VAR(P26:P144) -> 0.0046642938 | Q19: =VAR(Q26:Q144) -> 0.002421123 | R19: =VAR(R26:R144) -> 0.0129495 | S19: =VAR(S26:S144) -> 0.0065735945 | T19: =VAR(T26:T144) -> 0.0070655973 | U19: =VAR(U26:U144) -> 0.004243126 | ... X19: =VAR(X26:X144) -> 0.0016155666
A20: Beta (cov/var) | B20: =N20/$X$19 -> 1.1078162 | C20: =O20/$X$19 -> 1.2479038 | D20: =P20/$X$19 -> 1.2145693 | E20: =Q20/$X$19 -> 0.36804107 | F20: =R20/$X$19 -> 1.5224637 | G20: =S20/$X$19 -> 1.0963882 | H20: =T20/$X$19 -> 1.5140348 | I20: =U20/$X$19 -> 0.95018424 | ... K20: =W20/$X$19 -> 0.85510026 | L20: 1 | M20: Covariance | N20: =COVAR(N26:N144,$X$26:$X$144) -> 0.0017897509 | O20: =COVAR(O26:O144,$X$26:$X$144) -> 0.0020160717 | P20: =COVAR(P26:P144,$X$26:$X$144) -> 0.0019622176 | Q20: =COVAR(Q26:Q144,$X$26:$X$144) -> 0.00059459488 | R20: =COVAR(R26:R144,$X$26:$X$144) -> 0.0024596415 | S20: =COVAR(S26:S144,$X$26:$X$144) -> 0.0017712882 | T20: =COVAR(T26:T144,$X$26:$X$144) -> 0.002446024 | U20: =COVAR(U26:U144,$X$26:$X$144) -> 0.001535086 | ... W20: =COVAR(W26:W144,$X$26:$X$144) -> 0.0013814714
M21: Stdev | N21: =STDEV(N26:N144) -> 0.07950755 | O21: =STDEV(O26:O144) -> 0.091294079 | P21: =STDEV(P26:P144) -> 0.068295635 | Q21: =STDEV(Q26:Q144) -> 0.049204908 | R21: =STDEV(R26:R144) -> 0.11379587 | S21: =STDEV(S26:S144) -> 0.081077707 | T21: =STDEV(T26:T144) -> 0.084057107 | U21: =STDEV(U26:U144) -> 0.065139282 | ... X21: =STDEV(X26:X144) -> 0.040194112
M22: Variance | N22: =N21^2 -> 0.0063214505 | O22: =O21^2 -> 0.0083346089 | P22: =P21^2 -> 0.0046642938 | Q22: =Q21^2 -> 0.002421123 | R22: =R21^2 -> 0.0129495 | S22: =S21^2 -> 0.0065735945 | T22: =T21^2 -> 0.0070655973 | U22: =U21^2 -> 0.004243126 | ... X22: =X21^2 -> 0.0016155666
A23: Closing Prices | N23: Monthly Returns | Z23: Excess Returns
A24: Date | B24: AAPL | C24: HOG | D24: DIS | E24: WMT | F24: BBY | G24: AMZN | H24: GS | I24: GOOG | J24: HD | K24: MSFT | L24: S&P500 | N24: =B24 -> AAPL | O24: =C24 -> HOG | P24: =D24 -> DIS | Q24: =E24 -> WMT | R24: =F24 -> BBY | S24: =G24 -> AMZN | T24: =H24 -> GS | U24: =I24 -> GOOG | ... X24: =L24 -> S&P500 | Z24: =N24 -> AAPL | AA24: =O24 -> HOG | AB24: =P24 -> DIS | AC24: =Q24 -> WMT | AD24: =R24 -> BBY | AE24: =S24 -> AMZN | AF24: =T24 -> GS | AG24: =U24 -> GOOG | ... AI24: =W24 -> MSFT
A25: 40575 | B25: 10.882033 | C25: 32.462879 | D25: 38.515556 | E25: 40.593494 | F25: 23.9723 | G25: 173.28999 | H25: 140.5349 | I25: 305.55472 | J25: 29.789774 | K25: 21.132957 | L25: 109.11832
A26: 40603 | B26: 10.737231 | C26: 33.870445 | D26: 37.943199 | E26: 40.648159 | F26: 21.354977 | G26: 180.13001 | H26: 136.37917 | I26: 292.28445 | J26: 29.463816 | K26: 20.306141 | L26: 108.65939 | N26: =(B26/B25)-1 -> -0.013306521 | O26: =(C26/C25)-1 -> 0.043359247 | P26: =(D26/D25)-1 -> -0.014860411 | Q26: =(E26/E25)-1 -> 0.0013466444 | R26: =(F26/F25)-1 -> -0.10918114 | S26: =(G26/G25)-1 -> 0.039471477 | T26: =(H26/H25)-1 -> -0.029570812 | U26: =(I26/I25)-1 -> -0.043430074 | ... X26: =(L26/L25)-1 -> -0.0042058108 | Z26: =N26-N$18 -> -0.037275518 | AA26: =O26-O$18 -> 0.037239462 | AB26: =P26-P$18 -> -0.029738688 | AC26: =Q26-Q$18 -> -0.010582158 | AD26: =R26-R$18 -> -0.12881623 | AE26: =S26-S$18 -> 0.011772274 | AF26: =T26-T$18 -> -0.03948031 | AG26: =U26-U$18 -> -0.060181995 | ... AI26: =W26-W$18 -> -0.060348979
A27: 40634 | B27: 10.787144 | C27: 29.701408 | D27: 37.952 | E27: 43.237282 | F27: 23.213869 | G27: 195.81 | H27: 129.85255 | I27: 271.03409 | J27: 29.736994 | K27: 20.730015 | L27: 112.29202 | N27: =(B27/B26)-1 -> 0.0046485914 | O27: =(C27/C26)-1 -> -0.12308775 | P27: =(D27/D26)-1 -> 0.00023195198 | Q27: =(E27/E26)-1 -> 0.063695947 | R27: =(F27/F26)-1 -> 0.087047249 | S27: =(G27/G26)-1 -> 0.087048202 | T27: =(H27/H26)-1 -> -0.047856371 | U27: =(I27/I26)-1 -> -0.0727044 | ... X27: =(L27/L26)-1 -> 0.033431415 | Z27: =N27-N$18 -> -0.019320406 | AA27: =O27-O$18 -> -0.12920754 | AB27: =P27-P$18 -> -0.014646324 | AC27: =Q27-Q$18 -> 0.051767145 | AD27: =R27-R$18 -> 0.06741216 | AE27: =S27-S$18 -> 0.059348998 | AF27: =T27-T$18 -> -0.05776587 | AG27: =U27-U$18 -> -0.089456321 | ... AI27: =W27-W$18 -> -0.00035031901
A28: 40664 | B28: 10.71628 | C28: 29.6217 | D28: 36.657589 | E28: 43.426029 | F28: 23.732065 | G28: 196.69 | H28: 121.01286 | I28: 263.52225 | J28: 29.040598 | K28: 20.002222 | L28: 111.03271 | N28: =(B28/B27)-1 -> -0.0065693014 | O28: =(C28/C27)-1 -> -0.0026836438 | P28: =(D28/D27)-1 -> -0.034106529 | Q28: =(E28/E27)-1 -> 0.0043653762 | R28: =(F28/F27)-1 -> 0.02232269 | S28: =(G28/G27)-1 -> 0.004494173 | T28: =(H28/H27)-1 -> -0.068074834 | U28: =(I28/I27)-1 -> -0.027715484 | ... X28: =(L28/L27)-1 -> -0.011214581 | Z28: =N28-N$18 -> -0.030538299 | AA28: =O28-O$18 -> -0.0088034294 | AB28: =P28-P$18 -> -0.048984806 | AC28: =Q28-Q$18 -> -0.0075634258 | AD28: =R28-R$18 -> 0.0026876006 | AE28: =S28-S$18 -> -0.02320503 | AF28: =T28-T$18 -> -0.077984332 | AG28: =U28-U$18 -> -0.044467405 | ... AI28: =W28-W$18 -> -0.056332672
A29: 40695 | B29: 10.341642 | C29: 32.769939 | D29: 34.376938 | E29: 42.066776 | F29: 23.470537 | G29: 204.49 | H29: 114.73796 | I29: 252.24452 | J29: 28.992563 | K29: 20.930302 | L29: 108.6211 | N29: =(B29/B28)-1 -> -0.034959706 | O29: =(C29/C28)-1 -> 0.10628151 | P29: =(D29/D28)-1 -> -0.062214975 | Q29: =(E29/E28)-1 -> -0.031300421 | R29: =(F29/F28)-1 -> -0.011020027 | S29: =(G29/G28)-1 -> 0.039656327 | T29: =(H29/H28)-1 -> -0.051853182 | U29: =(I29/I28)-1 -> -0.042796102 | ... X29: =(L29/L28)-1 -> -0.021719851 | Z29: =N29-N$18 -> -0.058928703 | AA29: =O29-O$18 -> 0.10016172 | AB29: =P29-P$18 -> -0.077093252 | AC29: =Q29-Q$18 -> -0.043229223 | AD29: =R29-R$18 -> -0.030655116 | AE29: =S29-S$18 -> 0.011957123 | AF29: =T29-T$18 -> -0.06176268 | AG29: =U29-U$18 -> -0.059548023 | ... AI29: =W29-W$18 -> 0.025174348
A30: 40725 | B30: 12.030284 | C30: 34.705574 | D30: 34.007111 | E30: 41.726364 | F30: 20.721733 | G30: 222.52 | H30: 116.35873 | I30: 300.71783 | J30: 28.170143 | K30: 22.057314 | L30: 106.97594 | N30: =(B30/B29)-1 -> 0.16328568 | O30: =(C30/C29)-1 -> 0.059067397 | P30: =(D30/D29)-1 -> -0.010757997 | Q30: =(E30/E29)-1 -> -0.0080921818 | R30: =(F30/F29)-1 -> -0.11711722 | S30: =(G30/G29)-1 -> 0.088170564 | T30: =(H30/H29)-1 -> 0.014125804 | U30: =(I30/I29)-1 -> 0.19216795 | ... X30: =(L30/L29)-1 -> -0.015145823 | Z30: =N30-N$18 -> 0.13931668 | AA30: =O30-O$18 -> 0.052947612 | AB30: =P30-P$18 -> -0.025636274 | AC30: =Q30-Q$18 -> -0.020020984 | AD30: =R30-R$18 -> -0.13675231 | AE30: =S30-S$18 -> 0.06047136 | AF30: =T30-T$18 -> 0.004216306 | AG30: =U30-U$18 -> 0.17541603 | ... AI30: =W30-W$18 -> 0.032621453
A31: 40756 | B31: 11.856214 | C31: 30.922277 | D31: 29.991772 | E31: 42.106354 | F31: 19.212646 | G31: 215.23 | H31: 100.19421 | I31: 269.46997 | J31: 26.920107 | K31: 21.413305 | L31: 101.09486 | N31: =(B31/B30)-1 -> -0.014469318 | O31: =(C31/C30)-1 -> -0.10901122 | P31: =(D31/D30)-1 -> -0.11807351 | Q31: =(E31/E30)-1 -> 0.0091067125 | R31: =(F31/F30)-1 -> -0.072826293 | S31: =(G31/G30)-1 -> -0.032761135 | T31: =(H31/H30)-1 -> -0.13891964 | U31: =(I31/I30)-1 -> -0.10391091 | ... X31: =(L31/L30)-1 -> -0.054975733 | Z31: =N31-N$18 -> -0.038438315 | AA31: =O31-O$18 -> -0.11513101 | AB31: =P31-P$18 -> -0.13295179 | AC31: =Q31-Q$18 -> -0.0028220895 | AD31: =R31-R$18 -> -0.092461382 | AE31: =S31-S$18 -> -0.060460339 | AF31: =T31-T$18 -> -0.14882914 | AG31: =U31-U$18 -> -0.12066283 | ... AI31: =W31-W$18 -> -0.05042157
A32: 40787 | B32: 11.748072 | C32: 27.458914 | D32: 26.557594 | E32: 41.382385 | F32: 17.493347 | G32: 216.23 | H32: 81.75885 | I32: 256.55835 | J32: 26.705229 | K32: 20.163198 | L32: 93.59256 | N32: =(B32/B31)-1 -> -0.0091211242 | O32: =(C32/C31)-1 -> -0.1120022 | P32: =(D32/D31)-1 -> -0.114504 | Q32: =(E32/E31)-1 -> -0.017193818 | R32: =(F32/F31)-1 -> -0.089487882 | S32: =(G32/G31)-1 -> 0.0046461925 | T32: =(H32/H31)-1 -> -0.18399629 | U32: =(I32/I31)-1 -> -0.047914879 | ... X32: =(L32/L31)-1 -> -0.074210536 | Z32: =N32-N$18 -> -0.033090121 | AA32: =O32-O$18 -> -0.11812198 | AB32: =P32-P$18 -> -0.12938228 | AC32: =Q32-Q$18 -> -0.02912262 | AD32: =R32-R$18 -> -0.10912297 | AE32: =S32-S$18 -> -0.023053011 | AF32: =T32-T$18 -> -0.19390579 | AG32: =U32-U$18 -> -0.064666799 | ... AI32: =W32-W$18 -> -0.079604415
A33: 40817 | B33: 12.470849 | C33: 31.222103 | D33: 30.713825 | E33: 45.225601 | F33: 19.823248 | G33: 213.51 | H33: 94.729591 | I33: 295.21347 | J33: 29.085709 | K33: 21.572758 | L33: 104.34501 | N33: =(B33/B32)-1 -> 0.061523031 | O33: =(C33/C32)-1 -> 0.13704799 | P33: =(D33/D32)-1 -> 0.15649878 | Q33: =(E33/E32)-1 -> 0.092870819 | R33: =(F33/F32)-1 -> 0.13318783 | S33: =(G33/G32)-1 -> -0.012579203 | T33: =(H33/H32)-1 -> 0.15864632 | U33: =(I33/I32)-1 -> 0.15066795 | ... X33: =(L33/L32)-1 -> 0.11488572 | Z33: =N33-N$18 -> 0.037554034 | AA33: =O33-O$18 -> 0.13092821 | AB33: =P33-P$18 -> 0.1416205 | AC33: =Q33-Q$18 -> 0.080942017 | AD33: =R33-R$18 -> 0.11355274 | AE33: =S33-S$18 -> -0.040278406 | AF33: =T33-T$18 -> 0.14873683 | AG33: =U33-U$18 -> 0.13391603 | ... AI33: =W33-W$18 -> 0.048683064
A34: 40848 | B34: 11.775183 | C34: 29.512518 | D34: 31.567965 | E34: 46.963821 | F34: 20.473192 | G34: 192.28999 | H34: 82.89164 | I34: 298.57587 | J34: 31.864286 | K34: 20.722164 | L34: 103.92095 | N34: =(B34/B33)-1 -> -0.055783371 | O34: =(C34/C33)-1 -> -0.054755601 | P34: =(D34/D33)-1 -> 0.027809626 | Q34: =(E34/E33)-1 -> 0.038434426 | R34: =(F34/F33)-1 -> 0.032786958 | S34: =(G34/G33)-1 -> -0.099386457 | T34: =(H34/H33)-1 -> -0.12496571 | U34: =(I34/I33)-1 -> 0.011389714 | ... X34: =(L34/L33)-1 -> -0.0040639893 | Z34: =N34-N$18 -> -0.079752369 | AA34: =O34-O$18 -> -0.060875386 | AB34: =P34-P$18 -> 0.01293135 | AC34: =Q34-Q$18 -> 0.026505624 | AD34: =R34-R$18 -> 0.013151869 | AE34: =S34-S$18 -> -0.12708566 | AF34: =T34-T$18 -> -0.13487521 | AG34: =U34-U$18 -> -0.0053622066 | ... AI34: =W34-W$18 -> -0.060653577
A35: 40878 | B35: 12.477631 | C35: 31.198015 | D35: 33.020885 | E35: 47.649529 | F35: 17.661816 | G35: 173.10001 | H35: 78.498886 | I35: 321.74402 | J35: 34.423031 | K35: 21.188354 | L35: 104.34501 | N35: =(B35/B34)-1 -> 0.059654954 | O35: =(C35/C34)-1 -> 0.057111257 | P35: =(D35/D34)-1 -> 0.04602514 | Q35: =(E35/E34)-1 -> 0.014600771 | R35: =(F35/F34)-1 -> -0.13731987 | S35: =(G35/G34)-1 -> -0.099797117 | T35: =(H35/H34)-1 -> -0.052993933 | U35: =(I35/I34)-1 -> 0.077595528 | ... X35: =(L35/L34)-1 -> 0.0040805727 | Z35: =N35-N$18 -> 0.035685957 | AA35: =O35-O$18 -> 0.050991471 | AB35: =P35-P$18 -> 0.031146863 | AC35: =Q35-Q$18 -> 0.0026719691 | AD35: =R35-R$18 -> -0.15695496 | AE35: =S35-S$18 -> -0.12749632 | AF35: =T35-T$18 -> -0.062903431 | AG35: =U35-U$18 -> 0.060843607 | ... AI35: =W35-W$18 -> 0.0012726708
A36: 40909 | B36: 14.063673 | C36: 35.587414 | D36: 34.828869 | E36: 49.230999 | F36: 18.226936 | G36: 194.44 | H36: 96.762901 | I36: 288.97186 | J36: 36.347233 | K36: 24.102163 | L36: 109.87642 | N36: =(B36/B35)-1 -> 0.12711083 | O36: =(C36/C35)-1 -> 0.14069482 | P36: =(D36/D35)-1 -> 0.054752742 | Q36: =(E36/E35)-1 -> 0.033189625 | R36: =(F36/F35)-1 -> 0.03199671 | S36: =(G36/G35)-1 -> 0.12328131 | T36: =(H36/H35)-1 -> 0.23266591 | U36: =(I36/I35)-1 -> -0.10185786 | ... X36: =(L36/L35)-1 -> 0.053010777 | Z36: =N36-N$18 -> 0.10314183 | AA36: =O36-O$18 -> 0.13457503 | AB36: =P36-P$18 -> 0.039874466 | AC36: =Q36-Q$18 -> 0.021260823 | AD36: =R36-R$18 -> 0.01236162 | AE36: =S36-S$18 -> 0.09558211 | AF36: =T36-T$18 -> 0.22275641 | AG36: =U36-U$18 -> -0.11860978 | ... AI36: =W36-W$18 -> 0.11629487
A37: 40940 | B37: 16.712011 | C37: 37.512135 | D37: 37.595486 | E37: 47.401695 | F37: 18.797726 | G37: 179.69 | H37: 99.948723 | I37: 307.97064 | J37: 38.951077 | K37: 25.905951 | L37: 114.64564 | N37: =(B37/B36)-1 -> 0.18831055 | O37: =(C37/C36)-1 -> 0.054084318 | P37: =(D37/D36)-1 -> 0.079434592 | Q37: =(E37/E36)-1 -> -0.037157564 | R37: =(F37/F36)-1 -> 0.031315741 | S37: =(G37/G36)-1 -> -0.075858876 | T37: =(H37/H36)-1 -> 0.032924003 | U37: =(I37/I36)-1 -> 0.065746121 | ... X37: =(L37/L36)-1 -> 0.043405301 | Z37: =N37-N$18 -> 0.16434155 | AA37: =O37-O$18 -> 0.047964532 | AB37: =P37-P$18 -> 0.064556316 | AC37: =Q37-Q$18 -> -0.049086366 | AD37: =R37-R$18 -> 0.011680651 | AE37: =S37-S$18 -> -0.10355808 | AF37: =T37-T$18 -> 0.023014504 | AG37: =U37-U$18 -> 0.0489942 | ... AI37: =W37-W$18 -> 0.053614761
... A144: 44197 | B144: 127.14 | C144: 40.619999 | D144: 171.44 | E144: 144.64 | F144: 114 | G144: 3104.25 | H144: 301.01001 | I144: 1736.1899 | J144: 275.59 | K144: 212.64999 | L144: 375.70001 | N144: =(B144/B143)-1 -> -0.041826836 | O144: =(C144/C143)-1 -> 0.10736984 | P144: =(D144/D143)-1 -> -0.053758645 | Q144: =(E144/E143)-1 -> 0.0070670078 | R144: =(F144/F143)-1 -> 0.14867906 | S144: =(G144/G143)-1 -> -0.046878482 | T144: =(H144/H143)-1 -> 0.14766492 | U144: =(I144/I143)-1 -> -0.0089561294 | ... X144: =(L144/L143)-1 -> 0.0091512638 | Z144: =N144-N$18 -> -0.065795834 | AA144: =O144-O$18 -> 0.10125006 | AB144: =P144-P$18 -> -0.068636922 | AC144: =Q144-Q$18 -> -0.0048617941 | AD144: =R144-R$18 -> 0.12904397 | AE144: =S144-S$18 -> -0.074577686 | AF144: =T144-T$18 -> 0.13775542 | AG144: =U144-U$18 -> -0.02570805 | ... AI144: =W144-W$18 -> -0.065150421

Sheet MVO - Efficient Frontier
A1: Efficient Frontier
B2: AAPL | C2: HOG | D2: DIS | E2: WMT | F2: BBY | G2: AMZN | H2: GS | I2: GOOG | J2: HD | K2: MSFT | L2: E[Rp] | N2: Your Portfolio
A3: Historical Return | B3: 0.28762797 | C3: 0.073437427 | D3: 0.17853932 | E3: 0.14314562 | F3: 0.23562107 | G3: 0.33239044 | H3: 0.11891398 | I3: 0.20102305 | J3: 0.24357696 | K3: 0.25469396 | L3: =SUMPRODUCT(Weights, Returns) -> 0.3200003 | N3: 0.2069 | O3: E[Ri]
L4: σp | M4: Total weights
A5: Weights | B5: 0.26074794 | C5: 0 | D5: 0 | E5: 0 | F5: 0 | G5: 0.73116295 | H5: 0 | I5: 0 | J5: 0.008089116 | K5: 0 | L5: =SQRT(A23)*SQRT(12) -> 0.24270022 | M5: =SUM(B5:K5) -> 1 | N5: 0.1636 | O5: σi
A7: (Σ) | B7: Variance/Covariance Matrix
B8: =B2 -> AAPL | C8: =C2 -> HOG | D8: =D2 -> DIS | E8: =E2 -> WMT | F8: =F2 -> BBY | G8: =G2 -> AMZN | H8: =H2 -> GS | I8: =I2 -> GOOG | ... K8: =K2 -> MSFT
A9: AAPL | B9: ='Input Data'!O5 -> 0.0062683291 | C9: ='Input Data'!P5 -> 0.0021650927 | D9: ='Input Data'!Q5 -> 0.0019005461 | E9: ='Input Data'!R5 -> 0.00073522416 | F9: ='Input Data'!S5 -> 0.0024860194 | G9: ='Input Data'!T5 -> 0.0025490706 | H9: ='Input Data'!U5 -> 0.0024429231 | I9: ='Input Data'!V5 -> 0.0019782212 | ... K9: ='Input Data'!X5 -> 0.0021984751
A10: HOG | B10: ='Input Data'!O6 -> 0.0021650927 | C10: ='Input Data'!P6 -> 0.0082645702 | D10: ='Input Data'!Q6 -> 0.0021395626 | E10: ='Input Data'!R6 -> 0.00059013112 | F10: ='Input Data'!S6 -> 0.0042571289 | G10: ='Input Data'!T6 -> 0.0013094801 | H10: ='Input Data'!U6 -> 0.0034605155 | I10: ='Input Data'!V6 -> 0.0018259397 | ... K10: ='Input Data'!X6 -> 0.0012973234
A11: DIS | B11: ='Input Data'!O7 -> 0.0019005461 | C11: ='Input Data'!P7 -> 0.0021395626 | D11: ='Input Data'!Q7 -> 0.0046250981 | E11: ='Input Data'!R7 -> 0.00074802785 | F11: ='Input Data'!S7 -> 0.0024355442 | G11: ='Input Data'!T7 -> 0.0015163231 | H11: ='Input Data'!U7 -> 0.0032823531 | I11: ='Input Data'!V7 -> 0.001853103 | ... K11: ='Input Data'!X7 -> 0.0016172431
A12: WMT | B12: ='Input Data'!O8 -> 0.00073522416 | C12: ='Input Data'!P8 -> 0.00059013112 | D12: ='Input Data'!Q8 -> 0.00074802785 | E12: ='Input Data'!R8 -> 0.0024007774 | F12: ='Input Data'!S8 -> 0.0012862229 | G12: ='Input Data'!T8 -> 0.0005235213 | H12: ='Input Data'!U8 -> 0.00043778836 | I12: ='Input Data'!V8 -> 0.00027728847 | ... K12: ='Input Data'!X8 -> 0.00032422959
A13: BBY | B13: ='Input Data'!O9 -> 0.0024860194 | C13: ='Input Data'!P9 -> 0.0042571289 | D13: ='Input Data'!Q9 -> 0.0024355442 | E13: ='Input Data'!R9 -> 0.0012862229 | F13: ='Input Data'!S9 -> 0.012840681 | G13: ='Input Data'!T9 -> 0.0023799851 | H13: ='Input Data'!U9 -> 0.0038282457 | I13: ='Input Data'!V9 -> 0.0016219221 | ... K13: ='Input Data'!X9 -> 0.0019526734
A14: AMZN | B14: ='Input Data'!O10 -> 0.0025490706 | C14: ='Input Data'!P10 -> 0.0013094801 | D14: ='Input Data'!Q10 -> 0.0015163231 | E14: ='Input Data'!R10 -> 0.0005235213 | F14: ='Input Data'!S10 -> 0.0023799851 | G14: ='Input Data'!T10 -> 0.0065183542 | H14: ='Input Data'!U10 -> 0.0018019646 | I14: ='Input Data'!V10 -> 0.0024402518 | ... K14: ='Input Data'!X10 -> 0.0021806291
A15: GS | B15: ='Input Data'!O11 -> 0.0024429231 | C15: ='Input Data'!P11 -> 0.0034605155 | D15: ='Input Data'!Q11 -> 0.0032823531 | E15: ='Input Data'!R11 -> 0.00043778836 | F15: ='Input Data'!S11 -> 0.0038282457 | G15: ='Input Data'!T11 -> 0.0018019646 | H15: ='Input Data'!U11 -> 0.0070062225 | I15: ='Input Data'!V11 -> 0.0019688326 | ... K15: ='Input Data'!X11 -> 0.0019719049
A16: GOOG | B16: ='Input Data'!O12 -> 0.0019782212 | C16: ='Input Data'!P12 -> 0.0018259397 | D16: ='Input Data'!Q12 -> 0.001853103 | E16: ='Input Data'!R12 -> 0.00027728847 | F16: ='Input Data'!S12 -> 0.0016219221 | G16: ='Input Data'!T12 -> 0.0024402518 | H16: ='Input Data'!U12 -> 0.0019688326 | I16: ='Input Data'!V12 -> 0.0042074695 | ... K16: ='Input Data'!X12 -> 0.0016715542
A17: HD | B17: ='Input Data'!O13 -> 0.0013409445 | C17: ='Input Data'!P13 -> 0.0021653216 | D17: ='Input Data'!Q13 -> 0.0017526183 | E17: ='Input Data'!R13 -> 0.00059103623 | F17: ='Input Data'!S13 -> 0.0025563997 | G17: ='Input Data'!T13 -> 0.0016845749 | H17: ='Input Data'!U13 -> 0.0020984724 | I17: ='Input Data'!V13 -> 0.001644533 | ... K17: ='Input Data'!X13 -> 0.001116458
A18: MSFT | B18: ='Input Data'!O14 -> 0.0021984751 | C18: ='Input Data'!P14 -> 0.0012973234 | D18: ='Input Data'!Q14 -> 0.0016172431 | E18: ='Input Data'!R14 -> 0.00032422959 | F18: ='Input Data'!S14 -> 0.0019526734 | G18: ='Input Data'!T14 -> 0.0021806291 | H18: ='Input Data'!U14 -> 0.0019719049 | I18: ='Input Data'!V14 -> 0.0016715542 | ... K18: ='Input Data'!X14 -> 0.0033509278
A21: 0.32 | B21: Target Portfolio Return
A23: {=MMULT(Weights,MMULT(Covar,TRANSPOSE(Weights)))} -> 0.0049086166 | B23: Portfolio Variance
A29: Sample Portfolio Optimization Table -- (select target portfolio means)
A30: Use 'Paste Special' -> 'Values' from the 'Solver' results
B31: Weights
A32: Port Mean | B32: AAPL | C32: HOG | D32: DIS | E32: WMT | F32: BBY | G32: AMZN | H32: GS | I32: GOOG | J32: HD | K32: MSFT | L32: Port Sigma | M32: Port Mean
A33: 0.12 | B33: -1e-07 | C33: 0.28672138 | D33: 0 | E33: 0.58292094 | F33: 0 | G33: 0 | H33: 0.13035778 | I33: 0 | J33: 0 | K33: 0 | L33: 0.16012763 | M33: =A33 -> 0.12
A34: 0.14 | B34: 0 | C34: 0.13410606 | D34: 0.0015164772 | E34: 0.6079056 | F34: 0 | G34: 0 | H34: 0.11134342 | I34: 0.1367931 | J34: 0 | K34: 0.0083353435 | L34: 0.14077262 | M34: =A34 -> 0.14
A35: 0.16 | B35: 0 | C35: 0.087646539 | D35: 0.015179143 | E35: 0.5501153 | F35: 0 | G35: 0 | H35: 0.062755055 | I35: 0.13738196 | J35: 0.035328441 | K35: 0.11159356 | L35: 0.13156727 | M35: =A35 -> 0.16
A36: 0.18 | B36: 0 | C36: 0.044733071 | D36: 0.013551237 | E36: 0.4902764 | F36: 0 | G36: 0 | H36: 0.021768073 | I36: 0.11941336 | J36: 0.13487789 | K36: 0.17537995 | L36: 0.1265993 | M36: =A36 -> 0.18
A37: 0.2 | B37: 0.006347113 | C37: 0 | D37: 0.011214414 | E37: 0.42372581 | F37: 0 | G37: 0.0097158079 | H37: 0 | I37: 0.093885635 | J37: 0.22479202 | K37: 0.23031921 | L37: 0.12584672 | M37: =A37 -> 0.2
A38: 0.22 | B38: 0.042086449 | C38: 0 | D38: 0 | E38: 0.33348536 | F38: 0 | G38: 0.073293307 | H38: 0 | I38: 0.027638459 | J38: 0.27807412 | K38: 0.24542232 | L38: 0.13005479 | M38: =A38 -> 0.22
A39: 0.24 | B39: 0.077014848 | C39: 0 | D39: 0 | E39: 0.22031389 | F39: 0 | G39: 0.13941661 | H39: 0 | I39: 0 | J39: 0.31365457 | K39: 0.24960008 | L39: 0.13964671 | M39: =A39 -> 0.24
A40: 0.26 | B40: 0.11204679 | C40: 0 | D40: 0 | E40: 0.095299484 | F40: 0 | G40: 0.20628194 | H40: 0 | I40: 0 | J40: 0.34010891 | K40: 0.24626288 | L40: 0.15455417 | M40: =A40 -> 0.26
A41: 0.28 | B41: 0.15260132 | C41: 0 | D41: 0 | E41: 0 | F41: 0 | G41: 0.30754546 | H41: 0 | I41: 0 | J41: 0.32517155 | K41: 0.21468168 | L41: 0.17385596 | M41: =A41 -> 0.28
A42: 0.3 | B42: 0.21086885 | C42: 0 | D42: 0 | E42: 0 | F42: 0 | G42: 0.51913099 | H42: 0 | I42: 0 | J42: 0.17748408 | K42: 0.092516093 | L42: 0.20363666 | M42: =A42 -> 0.3
A43: 0.32 | B43: 0.26074794 | C43: 0 | D43: 0 | E43: 0 | F43: 0 | G43: 0.73116295 | H43: 0 | I43: 0 | J43: 0.008089116 | K43: 0 | L43: 0.24270022 | M43: =A43 -> 0.32
M44: =A44 -> 0
M45: =A45 -> 0
M46: =A46 -> 0
M47: =A47 -> 0
M48: =A48 -> 0
M49: =A49 -> 0
...

Sheet MVO Graph
